Workbook

Sheet השוואת פקטורים
A1: סהכ
A2: פנימי | B2: כלי להשוואת פקטורים בין שיטות חישוב PPR
B3: סוג PPR | C3: שיטה | D3: פקטור ממוצע | J3: שיטת חישוב (עמודה i+1 היא שיטה i+1 חלקי שיטה i)
B4: פנימי | C4: SPPR_new_GE | D4: מודל מאוזן | E4: SPPR מאוזן | F4: SPPR לא התפוצץ | G4: כל הדרישות
D5: =AVERAGEIFS(Z7:Z113, Z7:Z113, "<100", Z7:Z113, ">0.01", $F$7:$F$113, TRUE) -> 3.2168691 | E5: =AVERAGEIFS(Z7:Z113, Z7:Z113, "<100", Z7:Z113, ">0.01", $G$7:$G$113, TRUE) -> 2.7775617 | F5: =AVERAGEIFS(Z7:Z113, Z7:Z113, "<100", Z7:Z113, ">0.01", $H$7:$H$113, TRUE) -> 2.7610239 | G5: =AVERAGEIFS(Z7:Z113, Z7:Z113, "<100", Z7:Z113, ">0.01", $I$7:$I$113, TRUE) -> 3.1796214
B6: מודל | C6: model is balanced | D6: DC rows sum to 1 | E6: catch is not negative | F6: מודל מאוזן | G6: SPPR מאוזן | H6: SPPR לא התפוצץ | I6: כל הדרישות | J6: SPPR_1995_mTL_global_TE_01 | K6: SPPR_1995_mTL_global_mTE | L6: SPPR_EwE_global_mTE | M6: SPPR_EwE_differential_TE | N6: SPPR_2015 | O6: SPPR_new_2015 | P6: SPPR_new_GE | Q6: SPPR_symbolic_GE_import_as_PP | R6: SPPR_symbolic_GE_import_as_DC | S6: SPPR_symbolic_GE_import_as_PP | T6: SPPR_symbolic_GE_import_as_DC | U6: =C4 -> SPPR_new_GE | Z6: מצטבר
B7: [2] Alaska, Prince William Sound 1980 | C7: TRUE | D7: TRUE | E7: TRUE | F7: =AND(C7:E7) -> TRUE | G7: =ABS(INDEX(טבלה5[[SPPR_1986]:[SPPR_symbolic_full_import_as_DC]],MATCH('השוואת פקטורים'!$B7,טבלה5[עמודה1],0),MATCH($C$4,טבלה5[[#Headers],[SPPR_1986]:[SPPR_symbolic_full_import_as_DC]],0))) < 5 -> TRUE | H7: =INDEX(טבלה3[[SPPR_1986]:[SPPR_symbolic_full_import_as_DC]],MATCH('השוואת פקטורים'!$B7,טבלה3[עמודה1],0),MATCH($C$4,טבלה3[[#Headers],[SPPR_1986]:[SPPR_symbolic_full_import_as_DC]],0)) -> TRUE | I7: =AND(C7:H7) -> TRUE | K7: =IF($B$4="סהכ", INDEX(טבלה1[[SPPR_1986]:[SPPR_symbolic_full_import_as_DC]], MATCH('השוואת פקטורים'!$B7, 'PPRs all'!$A$2:$A$108, 0), MATCH('השוואת פקטורים'!K$6, טבלה1[[#Headers],[SPPR_1986]:[SPPR_symbolic_full_import_as_DC]], 0)) / INDEX(טבלה1[[SPPR_1986]:[SPPR_symbolic_full_import_as_DC]], MATCH('השוואת פקטורים'!$B7, 'PPRs all'!$A$2:$A$108, 0), MATCH('השוואת פקטורים'!J$6, טבלה1[[#Headers],[SPPR_1986]:[SPPR_symbolic_full_import_as_DC]], 0)), INDEX(טבלה2[[SPPR_1986]:[SPPR_symbolic_full_import_as_DC]], MATCH('השוואת פקטורים'!$B7, 'PPRs inner'!$A$2:$A$108, 0), MATCH('השוואת פקטורים'!K$6, טבלה2[[#Headers],[SPPR_1986]:[SPPR_symbolic_full_import_as_DC]], 0)) / INDEX(טבלה2[[SPPR_1986]:[SPPR_symbolic_full_import_as_DC]], MATCH('השוואת פקטורים'!$B7, 'PPRs inner'!$A$2:$A$108, 0), MATCH('השוואת פקטורים'!J$6, טבלה2[[#Headers],[SPPR_1986]:[SPPR_symbolic_full_import_as_DC]], 0)) ) -> 0.01340867 | L7: =IF($B$4="סהכ", INDEX(טבלה1[[SPPR_1986]:[SPPR_symbolic_full_import_as_DC]], MATCH('השוואת פקטורים'!$B7, 'PPRs all'!$A$2:$A$108, 0), MATCH('השוואת פקטורים'!L$6, טבלה1[[#Headers],[SPPR_1986]:[SPPR_symbolic_full_import_as_DC]], 0)) / INDEX(טבלה1[[SPPR_1986]:[SPPR_symbolic_full_import_as_DC]], MATCH('השוואת פקטורים'!$B7, 'PPRs all'!$A$2:$A$108, 0), MATCH('השוואת פקטורים'!K$6, טבלה1[[#Headers],[SPPR_1986]:[SPPR_symbolic_full_import_as_DC]], 0)), INDEX(טבלה2[[SPPR_1986]:[SPPR_symbolic_full_import_as_DC]], MATCH('השוואת פקטורים'!$B7, 'PPRs inner'!$A$2:$A$108, 0), MATCH('השוואת פקטורים'!L$6, טבלה2[[#Headers],[SPPR_1986]:[SPPR_symbolic_full_import_as_DC]], 0)) / INDEX(טבלה2[[SPPR_1986]:[SPPR_symbolic_full_import_as_DC]], MATCH('השוואת פקטורים'!$B7, 'PPRs inner'!$A$2:$A$108, 0), MATCH('השוואת פקטורים'!K$6, טבלה2[[#Headers],[SPPR_1986]:[SPPR_symbolic_full_import_as_DC]], 0)) ) -> 1.0962893 | M7: =IF($B$4="סהכ", INDEX(טבלה1[[SPPR_1986]:[SPPR_symbolic_full_import_as_DC]], MATCH('השוואת פקטורים'!$B7, 'PPRs all'!$A$2:$A$108, 0), MATCH('השוואת פקטורים'!M$6, טבלה1[[#Headers],[SPPR_1986]:[SPPR_symbolic_full_import_as_DC]], 0)) / INDEX(טבלה1[[SPPR_1986]:[SPPR_symbolic_full_import_as_DC]], MATCH('השוואת פקטורים'!$B7, 'PPRs all'!$A$2:$A$108, 0), MATCH('השוואת פקטורים'!L$6, טבלה1[[#Headers],[SPPR_1986]:[SPPR_symbolic_full_import_as_DC]], 0)), INDEX(טבלה2[[SPPR_1986]:[SPPR_symbolic_full_import_as_DC]], MATCH('השוואת פקטורים'!$B7, 'PPRs inner'!$A$2:$A$108, 0), MATCH('השוואת פקטורים'!M$6, טבלה2[[#Headers],[SPPR_1986]:[SPPR_symbolic_full_import_as_DC]], 0)) / INDEX(טבלה2[[SPPR_1986]:[SPPR_symbolic_full_import_as_DC]], MATCH('השוואת פקטורים'!$B7, 'PPRs inner'!$A$2:$A$108, 0), MATCH('השוואת פקטורים'!L$6, טבלה2[[#Headers],[SPPR_1986]:[SPPR_symbolic_full_import_as_DC]], 0)) ) -> 21.308046 | N7: =IF($B$4="סהכ", INDEX(טבלה1[[SPPR_1986]:[SPPR_symbolic_full_import_as_DC]], MATCH('השוואת פקטורים'!$B7, 'PPRs all'!$A$2:$A$108, 0), MATCH('השוואת פקטורים'!N$6, טבלה1[[#Headers],[SPPR_1986]:[SPPR_symbolic_full_import_as_DC]], 0)) / INDEX(טבלה1[[SPPR_1986]:[SPPR_symbolic_full_import_as_DC]], MATCH('השוואת פקטורים'!$B7, 'PPRs all'!$A$2:$A$108, 0), MATCH('השוואת פקטורים'!M$6, טבלה1[[#Headers],[SPPR_1986]:[SPPR_symbolic_full_import_as_DC]], 0)), INDEX(טבלה2[[SPPR_1986]:[SPPR_symbolic_full_import_as_DC]], MATCH('השוואת פקטורים'!$B7, 'PPRs inner'!$A$2:$A$108, 0), MATCH('השוואת פקטורים'!N$6, טבלה2[[#Headers],[SPPR_1986]:[SPPR_symbolic_full_import_as_DC]], 0)) / INDEX(טבלה2[[SPPR_1986]:[SPPR_symbolic_full_import_as_DC]], MATCH('השוואת פקטורים'!$B7, 'PPRs inner'!$A$2:$A$108, 0), MATCH('השוואת פקטורים'!M$6, טבלה2[[#Headers],[SPPR_1986]:[SPPR_symbolic_full_import_as_DC]], 0)) ) -> 1.3085636 | O7: =IF($B$4="סהכ", INDEX(טבלה1[[SPPR_1986]:[SPPR_symbolic_full_import_as_DC]], MATCH('השוואת פקטורים'!$B7, 'PPRs all'!$A$2:$A$108, 0), MATCH('השוואת פקטורים'!O$6, טבלה1[[#Headers],[SPPR_1986]:[SPPR_symbolic_full_import_as_DC]], 0)) / INDEX(טבלה1[[SPPR_1986]:[SPPR_symbolic_full_import_as_DC]], MATCH('השוואת פקטורים'!$B7, 'PPRs all'!$A$2:$A$108, 0), MATCH('השוואת פקטורים'!N$6, טבלה1[[#Headers],[SPPR_1986]:[SPPR_symbolic_full_import_as_DC]], 0)), INDEX(טבלה2[[SPPR_1986]:[SPPR_symbolic_full_import_as_DC]], MATCH('השוואת פקטורים'!$B7, 'PPRs inner'!$A$2:$A$108, 0), MATCH('השוואת פקטורים'!O$6, טבלה2[[#Headers],[SPPR_1986]:[SPPR_symbolic_full_import_as_DC]], 0)) / INDEX(טבלה2[[SPPR_1986]:[SPPR_symbolic_full_import_as_DC]], MATCH('השוואת פקטורים'!$B7, 'PPRs inner'!$A$2:$A$108, 0), MATCH('השוואת פקטורים'!N$6, טבלה2[[#Headers],[SPPR_1986]:[SPPR_symbolic_full_import_as_DC]], 0)) ) -> 1 | P7: =IF($B$4="סהכ", INDEX(טבלה1[[SPPR_1986]:[SPPR_symbolic_full_import_as_DC]], MATCH('השוואת פקטורים'!$B7, 'PPRs all'!$A$2:$A$108, 0), MATCH('השוואת פקטורים'!P$6, טבלה1[[#Headers],[SPPR_1986]:[SPPR_symbolic_full_import_as_DC]], 0)) / INDEX(טבלה1[[SPPR_1986]:[SPPR_symbolic_full_import_as_DC]], MATCH('השוואת פקטורים'!$B7, 'PPRs all'!$A$2:$A$108, 0), MATCH('השוואת פקטורים'!O$6, טבלה1[[#Headers],[SPPR_1986]:[SPPR_symbolic_full_import_as_DC]], 0)), INDEX(טבלה2[[SPPR_1986]:[SPPR_symbolic_full_import_as_DC]], MATCH('השוואת פקטורים'!$B7, 'PPRs inner'!$A$2:$A$108, 0), MATCH('השוואת פקטורים'!P$6, טבלה2[[#Headers],[SPPR_1986]:[SPPR_symbolic_full_import_as_DC]], 0)) / INDEX(טבלה2[[SPPR_1986]:[SPPR_symbolic_full_import_as_DC]], MATCH('השוואת פקטורים'!$B7, 'PPRs inner'!$A$2:$A$108, 0), MATCH('השוואת פקטורים'!O$6, טבלה2[[#Headers],[SPPR_1986]:[SPPR_symbolic_full_import_as_DC]], 0)) ) -> 3.5678245 | Q7: =IF($B$4="סהכ", INDEX(טבלה1[[SPPR_1986]:[SPPR_symbolic_full_import_as_DC]], MATCH('השוואת פקטורים'!$B7, 'PPRs all'!$A$2:$A$108, 0), MATCH('השוואת פקטורים'!Q$6, טבלה1[[#Headers],[SPPR_1986]:[SPPR_symbolic_full_import_as_DC]], 0)) / INDEX(טבלה1[[SPPR_1986]:[SPPR_symbolic_full_import_as_DC]], MATCH('השוואת פקטורים'!$B7, 'PPRs all'!$A$2:$A$108, 0), MATCH('השוואת פקטורים'!P$6, טבלה1[[#Headers],[SPPR_1986]:[SPPR_symbolic_full_import_as_DC]], 0)), INDEX(טבלה2[[SPPR_1986]:[SPPR_symbolic_full_import_as_DC]], MATCH('השוואת פקטורים'!$B7, 'PPRs inner'!$A$2:$A$108, 0), MATCH('השוואת פקטורים'!Q$6, טבלה2[[#Headers],[SPPR_1986]:[SPPR_symbolic_full_import_as_DC]], 0)) / INDEX(טבלה2[[SPPR_1986]:[SPPR_symbolic_full_import_as_DC]], MATCH('השוואת פקטורים'!$B7, 'PPRs inner'!$A$2:$A$108, 0), MATCH('השוואת פקטורים'!P$6, טבלה2[[#Headers],[SPPR_1986]:[SPPR_symbolic_full_import_as_DC]], 0)) ) -> 1 | R7: =IF($B$4="סהכ", INDEX(טבלה1[[SPPR_1986]:[SPPR_symbolic_full_import_as_DC]], MATCH('השוואת פקטורים'!$B7, 'PPRs all'!$A$2:$A$108, 0), MATCH('השוואת פקטורים'!R$6, טבלה1[[#Headers],[SPPR_1986]:[SPPR_symbolic_full_import_as_DC]], 0)) / INDEX(טבלה1[[SPPR_1986]:[SPPR_symbolic_full_import_as_DC]], MATCH('השוואת פקטורים'!$B7, 'PPRs all'!$A$2:$A$108, 0), MATCH('השוואת פקטורים'!Q$6, טבלה1[[#Headers],[SPPR_1986]:[SPPR_symbolic_full_import_as_DC]], 0)), INDEX(טבלה2[[SPPR_1986]:[SPPR_symbolic_full_import_as_DC]], MATCH('השוואת פקטורים'!$B7, 'PPRs inner'!$A$2:$A$108, 0), MATCH('השוואת פקטורים'!R$6, טבלה2[[#Headers],[SPPR_1986]:[SPPR_symbolic_full_import_as_DC]], 0)) / INDEX(טבלה2[[SPPR_1986]:[SPPR_symbolic_full_import_as_DC]], MATCH('השוואת פקטורים'!$B7, 'PPRs inner'!$A$2:$A$108, 0), MATCH('השוואת פקטורים'!Q$6, טבלה2[[#Headers],[SPPR_1986]:[SPPR_symbolic_full_import_as_DC]], 0)) ) -> 1 | ... U7: =IF($B$4="סהכ", INDEX(טבלה1[[SPPR_1986]:[SPPR_symbolic_full_import_as_DC]], MATCH('השוואת פקטורים'!$B7, 'PPRs all'!$A$2:$A$108, 0), MATCH('השוואת פקטורים'!U$6, טבלה1[[#Headers],[SPPR_1986]:[SPPR_symbolic_full_import_as_DC]], 0)) / INDEX(טבלה1[[SPPR_1986]:[SPPR_symbolic_full_import_as_DC]], MATCH('השוואת פקטורים'!$B7, 'PPRs all'!$A$2:$A$108, 0), MATCH('השוואת פקטורים'!T$6, טבלה1[[#Headers],[SPPR_1986]:[SPPR_symbolic_full_import_as_DC]], 0)), INDEX(טבלה2[[SPPR_1986]:[SPPR_symbolic_full_import_as_DC]], MATCH('השוואת פקטורים'!$B7, 'PPRs inner'!$A$2:$A$108, 0), MATCH('השוואת פקטורים'!U$6, טבלה2[[#Headers],[SPPR_1986]:[SPPR_symbolic_full_import_as_DC]], 0)) / INDEX(טבלה2[[SPPR_1986]:[SPPR_symbolic_full_import_as_DC]], MATCH('השוואת פקטורים'!$B7, 'PPRs inner'!$A$2:$A$108, 0), MATCH('השוואת פקטורים'!T$6, טבלה2[[#Headers],[SPPR_1986]:[SPPR_symbolic_full_import_as_DC]], 0)) ) -> 1 | Z7: =PRODUCT(K7:Y7) -> 1.4623551
B8: [7] Azores archipelago 1997 | C8: TRUE | D8: TRUE | E8: TRUE | F8: =AND(C8:E8) -> TRUE | G8: =ABS(INDEX(טבלה5[[SPPR_1986]:[SPPR_symbolic_full_import_as_DC]],MATCH('השוואת פקטורים'!$B8,טבלה5[עמודה1],0),MATCH($C$4,טבלה5[[#Headers],[SPPR_1986]:[SPPR_symbolic_full_import_as_DC]],0))) < 5 -> TRUE | H8: =INDEX(טבלה3[[SPPR_1986]:[SPPR_symbolic_full_import_as_DC]],MATCH('השוואת פקטורים'!$B8,טבלה3[עמודה1],0),MATCH($C$4,טבלה3[[#Headers],[SPPR_1986]:[SPPR_symbolic_full_import_as_DC]],0)) -> TRUE | I8: =AND(C8:H8) -> TRUE | K8: =IF($B$4="סהכ", INDEX(טבלה1[[SPPR_1986]:[SPPR_symbolic_full_import_as_DC]], MATCH('השוואת פקטורים'!$B8, 'PPRs all'!$A$2:$A$108, 0), MATCH('השוואת פקטורים'!K$6, טבלה1[[#Headers],[SPPR_1986]:[SPPR_symbolic_full_import_as_DC]], 0)) / INDEX(טבלה1[[SPPR_1986]:[SPPR_symbolic_full_import_as_DC]], MATCH('השוואת פקטורים'!$B8, 'PPRs all'!$A$2:$A$108, 0), MATCH('השוואת פקטורים'!J$6, טבלה1[[#Headers],[SPPR_1986]:[SPPR_symbolic_full_import_as_DC]], 0)), INDEX(טבלה2[[SPPR_1986]:[SPPR_symbolic_full_import_as_DC]], MATCH('השוואת פקטורים'!$B8, 'PPRs inner'!$A$2:$A$108, 0), MATCH('השוואת פקטורים'!K$6, טבלה2[[#Headers],[SPPR_1986]:[SPPR_symbolic_full_import_as_DC]], 0)) / INDEX(טבלה2[[SPPR_1986]:[SPPR_symbolic_full_import_as_DC]], MATCH('השוואת פקטורים'!$B8, 'PPRs inner'!$A$2:$A$108, 0), MATCH('השוואת פקטורים'!J$6, טבלה2[[#Headers],[SPPR_1986]:[SPPR_symbolic_full_import_as_DC]], 0)) ) -> 0.7682839 | L8: =IF($B$4="סהכ", INDEX(טבלה1[[SPPR_1986]:[SPPR_symbolic_full_import_as_DC]], MATCH('השוואת פקטורים'!$B8, 'PPRs all'!$A$2:$A$108, 0), MATCH('השוואת פקטורים'!L$6, טבלה1[[#Headers],[SPPR_1986]:[SPPR_symbolic_full_import_as_DC]], 0)) / INDEX(טבלה1[[SPPR_1986]:[SPPR_symbolic_full_import_as_DC]], MATCH('השוואת פקטורים'!$B8, 'PPRs all'!$A$2:$A$108, 0), MATCH('השוואת פקטורים'!K$6, טבלה1[[#Headers],[SPPR_1986]:[SPPR_symbolic_full_import_as_DC]], 0)), INDEX(טבלה2[[SPPR_1986]:[SPPR_symbolic_full_import_as_DC]], MATCH('השוואת פקטורים'!$B8, 'PPRs inner'!$A$2:$A$108, 0), MATCH('השוואת פקטורים'!L$6, טבלה2[[#Headers],[SPPR_1986]:[SPPR_symbolic_full_import_as_DC]], 0)) / INDEX(טבלה2[[SPPR_1986]:[SPPR_symbolic_full_import_as_DC]], MATCH('השוואת פקטורים'!$B8, 'PPRs inner'!$A$2:$A$108, 0), MATCH('השוואת פקטורים'!K$6, טבלה2[[#Headers],[SPPR_1986]:[SPPR_symbolic_full_import_as_DC]], 0)) ) -> 5.6128815 | M8: =IF($B$4="סהכ", INDEX(טבלה1[[SPPR_1986]:[SPPR_symbolic_full_import_as_DC]], MATCH('השוואת פקטורים'!$B8, 'PPRs all'!$A$2:$A$108, 0), MATCH('השוואת פקטורים'!M$6, טבלה1[[#Headers],[SPPR_1986]:[SPPR_symbolic_full_import_as_DC]], 0)) / INDEX(טבלה1[[SPPR_1986]:[SPPR_symbolic_full_import_as_DC]], MATCH('השוואת פקטורים'!$B8, 'PPRs all'!$A$2:$A$108, 0), MATCH('השוואת פקטורים'!L$6, טבלה1[[#Headers],[SPPR_1986]:[SPPR_symbolic_full_import_as_DC]], 0)), INDEX(טבלה2[[SPPR_1986]:[SPPR_symbolic_full_import_as_DC]], MATCH('השוואת פקטורים'!$B8, 'PPRs inner'!$A$2:$A$108, 0), MATCH('השוואת פקטורים'!M$6, טבלה2[[#Headers],[SPPR_1986]:[SPPR_symbolic_full_import_as_DC]], 0)) / INDEX(טבלה2[[SPPR_1986]:[SPPR_symbolic_full_import_as_DC]], MATCH('השוואת פקטורים'!$B8, 'PPRs inner'!$A$2:$A$108, 0), MATCH('השוואת פקטורים'!L$6, טבלה2[[#Headers],[SPPR_1986]:[SPPR_symbolic_full_import_as_DC]], 0)) ) -> 2.156282 | N8: =IF($B$4="סהכ", INDEX(טבלה1[[SPPR_1986]:[SPPR_symbolic_full_import_as_DC]], MATCH('השוואת פקטורים'!$B8, 'PPRs all'!$A$2:$A$108, 0), MATCH('השוואת פקטורים'!N$6, טבלה1[[#Headers],[SPPR_1986]:[SPPR_symbolic_full_import_as_DC]], 0)) / INDEX(טבלה1[[SPPR_1986]:[SPPR_symbolic_full_import_as_DC]], MATCH('השוואת פקטורים'!$B8, 'PPRs all'!$A$2:$A$108, 0), MATCH('השוואת פקטורים'!M$6, טבלה1[[#Headers],[SPPR_1986]:[SPPR_symbolic_full_import_as_DC]], 0)), INDEX(טבלה2[[SPPR_1986]:[SPPR_symbolic_full_import_as_DC]], MATCH('השוואת פקטורים'!$B8, 'PPRs inner'!$A$2:$A$108, 0), MATCH('השוואת פקטורים'!N$6, טבלה2[[#Headers],[SPPR_1986]:[SPPR_symbolic_full_import_as_DC]], 0)) / INDEX(טבלה2[[SPPR_1986]:[SPPR_symbolic_full_import_as_DC]], MATCH('השוואת פקטורים'!$B8, 'PPRs inner'!$A$2:$A$108, 0), MATCH('השוואת פקטורים'!M$6, טבלה2[[#Headers],[SPPR_1986]:[SPPR_symbolic_full_import_as_DC]], 0)) ) -> 2.1095883 | O8: =IF($B$4="סהכ", INDEX(טבלה1[[SPPR_1986]:[SPPR_symbolic_full_import_as_DC]], MATCH('השוואת פקטורים'!$B8, 'PPRs all'!$A$2:$A$108, 0), MATCH('השוואת פקטורים'!O$6, טבלה1[[#Headers],[SPPR_1986]:[SPPR_symbolic_full_import_as_DC]], 0)) / INDEX(טבלה1[[SPPR_1986]:[SPPR_symbolic_full_import_as_DC]], MATCH('השוואת פקטורים'!$B8, 'PPRs all'!$A$2:$A$108, 0), MATCH('השוואת פקטורים'!N$6, טבלה1[[#Headers],[SPPR_1986]:[SPPR_symbolic_full_import_as_DC]], 0)), INDEX(טבלה2[[SPPR_1986]:[SPPR_symbolic_full_import_as_DC]], MATCH('השוואת פקטורים'!$B8, 'PPRs inner'!$A$2:$A$108, 0), MATCH('השוואת פקטורים'!O$6, טבלה2[[#Headers],[SPPR_1986]:[SPPR_symbolic_full_import_as_DC]], 0)) / INDEX(טבלה2[[SPPR_1986]:[SPPR_symbolic_full_import_as_DC]], MATCH('השוואת פקטורים'!$B8, 'PPRs inner'!$A$2:$A$108, 0), MATCH('השוואת פקטורים'!N$6, טבלה2[[#Headers],[SPPR_1986]:[SPPR_symbolic_full_import_as_DC]], 0)) ) -> 1 | P8: =IF($B$4="סהכ", INDEX(טבלה1[[SPPR_1986]:[SPPR_symbolic_full_import_as_DC]], MATCH('השוואת פקטורים'!$B8, 'PPRs all'!$A$2:$A$108, 0), MATCH('השוואת פקטורים'!P$6, טבלה1[[#Headers],[SPPR_1986]:[SPPR_symbolic_full_import_as_DC]], 0)) / INDEX(טבלה1[[SPPR_1986]:[SPPR_symbolic_full_import_as_DC]], MATCH('השוואת פקטורים'!$B8, 'PPRs all'!$A$2:$A$108, 0), MATCH('השוואת פקטורים'!O$6, טבלה1[[#Headers],[SPPR_1986]:[SPPR_symbolic_full_import_as_DC]], 0)), INDEX(טבלה2[[SPPR_1986]:[SPPR_symbolic_full_import_as_DC]], MATCH('השוואת פקטורים'!$B8, 'PPRs inner'!$A$2:$A$108, 0), MATCH('השוואת פקטורים'!P$6, טבלה2[[#Headers],[SPPR_1986]:[SPPR_symbolic_full_import_as_DC]], 0)) / INDEX(טבלה2[[SPPR_1986]:[SPPR_symbolic_full_import_as_DC]], MATCH('השוואת פקטורים'!$B8, 'PPRs inner'!$A$2:$A$108, 0), MATCH('השוואת פקטורים'!O$6, טבלה2[[#Headers],[SPPR_1986]:[SPPR_symbolic_full_import_as_DC]], 0)) ) -> 0.091854929 | Q8: =IF($B$4="סהכ", INDEX(טבלה1[[SPPR_1986]:[SPPR_symbolic_full_import_as_DC]], MATCH('השוואת פקטורים'!$B8, 'PPRs all'!$A$2:$A$108, 0), MATCH('השוואת פקטורים'!Q$6, טבלה1[[#Headers],[SPPR_1986]:[SPPR_symbolic_full_import_as_DC]], 0)) / INDEX(טבלה1[[SPPR_1986]:[SPPR_symbolic_full_import_as_DC]], MATCH('השוואת פקטורים'!$B8, 'PPRs all'!$A$2:$A$108, 0), MATCH('השוואת פקטורים'!P$6, טבלה1[[#Headers],[SPPR_1986]:[SPPR_symbolic_full_import_as_DC]], 0)), INDEX(טבלה2[[SPPR_1986]:[SPPR_symbolic_full_import_as_DC]], MATCH('השוואת פקטורים'!$B8, 'PPRs inner'!$A$2:$A$108, 0), MATCH('השוואת פקטורים'!Q$6, טבלה2[[#Headers],[SPPR_1986]:[SPPR_symbolic_full_import_as_DC]], 0)) / INDEX(טבלה2[[SPPR_1986]:[SPPR_symbolic_full_import_as_DC]], MATCH('השוואת פקטורים'!$B8, 'PPRs inner'!$A$2:$A$108, 0), MATCH('השוואת פקטורים'!P$6, טבלה2[[#Headers],[SPPR_1986]:[SPPR_symbolic_full_import_as_DC]], 0)) ) -> 1 | R8: =IF($B$4="סהכ", INDEX(טבלה1[[SPPR_1986]:[SPPR_symbolic_full_import_as_DC]], MATCH('השוואת פקטורים'!$B8, 'PPRs all'!$A$2:$A$108, 0), MATCH('השוואת פקטורים'!R$6, טבלה1[[#Headers],[SPPR_1986]:[SPPR_symbolic_full_import_as_DC]], 0)) / INDEX(טבלה1[[SPPR_1986]:[SPPR_symbolic_full_import_as_DC]], MATCH('השוואת פקטורים'!$B8, 'PPRs all'!$A$2:$A$108, 0), MATCH('השוואת פקטורים'!Q$6, טבלה1[[#Headers],[SPPR_1986]:[SPPR_symbolic_full_import_as_DC]], 0)), INDEX(טבלה2[[SPPR_1986]:[SPPR_symbolic_full_import_as_DC]], MATCH('השוואת פקטורים'!$B8, 'PPRs inner'!$A$2:$A$108, 0), MATCH('השוואת פקטורים'!R$6, טבלה2[[#Headers],[SPPR_1986]:[SPPR_symbolic_full_import_as_DC]], 0)) / INDEX(טבלה2[[SPPR_1986]:[SPPR_symbolic_full_import_as_DC]], MATCH('השוואת פקטורים'!$B8, 'PPRs inner'!$A$2:$A$108, 0), MATCH('השוואת פקטורים'!Q$6, טבלה2[[#Headers],[SPPR_1986]:[SPPR_symbolic_full_import_as_DC]], 0)) ) -> -716.66107 | ... U8: =IF($B$4="סהכ", INDEX(טבלה1[[SPPR_1986]:[SPPR_symbolic_full_import_as_DC]], MATCH('השוואת פקטורים'!$B8, 'PPRs all'!$A$2:$A$108, 0), MATCH('השוואת פקטורים'!U$6, טבלה1[[#Headers],[SPPR_1986]:[SPPR_symbolic_full_import_as_DC]], 0)) / INDEX(טבלה1[[SPPR_1986]:[SPPR_symbolic_full_import_as_DC]], MATCH('השוואת פקטורים'!$B8, 'PPRs all'!$A$2:$A$108, 0), MATCH('השוואת פקטורים'!T$6, טבלה1[[#Headers],[SPPR_1986]:[SPPR_symbolic_full_import_as_DC]], 0)), INDEX(טבלה2[[SPPR_1986]:[SPPR_symbolic_full_import_as_DC]], MATCH('השוואת פקטורים'!$B8, 'PPRs inner'!$A$2:$A$108, 0), MATCH('השוואת פקטורים'!U$6, טבלה2[[#Headers],[SPPR_1986]:[SPPR_symbolic_full_import_as_DC]], 0)) / INDEX(טבלה2[[SPPR_1986]:[SPPR_symbolic_full_import_as_DC]], MATCH('השוואת פקטורים'!$B8, 'PPRs inner'!$A$2:$A$108, 0), MATCH('השוואת פקטורים'!T$6, טבלה2[[#Headers],[SPPR_1986]:[SPPR_symbolic_full_import_as_DC]], 0)) ) -> -0.0013953597 | Z8: =PRODUCT(K8:Y8) -> 1.8018281
B9: [28] Central Atlantic 1950 | C9: TRUE | D9: TRUE | E9: TRUE | F9: =AND(C9:E9) -> TRUE | G9: =ABS(INDEX(טבלה5[[SPPR_1986]:[SPPR_symbolic_full_import_as_DC]],MATCH('השוואת פקטורים'!$B9,טבלה5[עמודה1],0),MATCH($C$4,טבלה5[[#Headers],[SPPR_1986]:[SPPR_symbolic_full_import_as_DC]],0))) < 5 -> TRUE | H9: =INDEX(טבלה3[[SPPR_1986]:[SPPR_symbolic_full_import_as_DC]],MATCH('השוואת פקטורים'!$B9,טבלה3[עמודה1],0),MATCH($C$4,טבלה3[[#Headers],[SPPR_1986]:[SPPR_symbolic_full_import_as_DC]],0)) -> TRUE | I9: =AND(C9:H9) -> TRUE | K9: =IF($B$4="סהכ", INDEX(טבלה1[[SPPR_1986]:[SPPR_symbolic_full_import_as_DC]], MATCH('השוואת פקטורים'!$B9, 'PPRs all'!$A$2:$A$108, 0), MATCH('השוואת פקטורים'!K$6, טבלה1[[#Headers],[SPPR_1986]:[SPPR_symbolic_full_import_as_DC]], 0)) / INDEX(טבלה1[[SPPR_1986]:[SPPR_symbolic_full_import_as_DC]], MATCH('השוואת פקטורים'!$B9, 'PPRs all'!$A$2:$A$108, 0), MATCH('השוואת פקטורים'!J$6, טבלה1[[#Headers],[SPPR_1986]:[SPPR_symbolic_full_import_as_DC]], 0)), INDEX(טבלה2[[SPPR_1986]:[SPPR_symbolic_full_import_as_DC]], MATCH('השוואת פקטורים'!$B9, 'PPRs inner'!$A$2:$A$108, 0), MATCH('השוואת פקטורים'!K$6, טבלה2[[#Headers],[SPPR_1986]:[SPPR_symbolic_full_import_as_DC]], 0)) / INDEX(טבלה2[[SPPR_1986]:[SPPR_symbolic_full_import_as_DC]], MATCH('השוואת פקטורים'!$B9, 'PPRs inner'!$A$2:$A$108, 0), MATCH('השוואת פקטורים'!J$6, טבלה2[[#Headers],[SPPR_1986]:[SPPR_symbolic_full_import_as_DC]], 0)) ) -> 0.11893574 | L9: =IF($B$4="סהכ", INDEX(טבלה1[[SPPR_1986]:[SPPR_symbolic_full_import_as_DC]], MATCH('השוואת פקטורים'!$B9, 'PPRs all'!$A$2:$A$108, 0), MATCH('השוואת פקטורים'!L$6, טבלה1[[#Headers],[SPPR_1986]:[SPPR_symbolic_full_import_as_DC]], 0)) / INDEX(טבלה1[[SPPR_1986]:[SPPR_symbolic_full_import_as_DC]], MATCH('השוואת פקטורים'!$B9, 'PPRs all'!$A$2:$A$108, 0), MATCH('השוואת פקטורים'!K$6, טבלה1[[#Headers],[SPPR_1986]:[SPPR_symbolic_full_import_as_DC]], 0)), INDEX(טבלה2[[SPPR_1986]:[SPPR_symbolic_full_import_as_DC]], MATCH('השוואת פקטורים'!$B9, 'PPRs inner'!$A$2:$A$108, 0), MATCH('השוואת פקטורים'!L$6, טבלה2[[#Headers],[SPPR_1986]:[SPPR_symbolic_full_import_as_DC]], 0)) / INDEX(טבלה2[[SPPR_1986]:[SPPR_symbolic_full_import_as_DC]], MATCH('השוואת פקטורים'!$B9, 'PPRs inner'!$A$2:$A$108, 0), MATCH('השוואת פקטורים'!K$6, טבלה2[[#Headers],[SPPR_1986]:[SPPR_symbolic_full_import_as_DC]], 0)) ) -> 2.1060897 | M9: =IF($B$4="סהכ", INDEX(טבלה1[[SPPR_1986]:[SPPR_symbolic_full_import_as_DC]], MATCH('השוואת פקטורים'!$B9, 'PPRs all'!$A$2:$A$108, 0), MATCH('השוואת פקטורים'!M$6, טבלה1[[#Headers],[SPPR_1986]:[SPPR_symbolic_full_import_as_DC]], 0)) / INDEX(טבלה1[[SPPR_1986]:[SPPR_symbolic_full_import_as_DC]], MATCH('השוואת פקטורים'!$B9, 'PPRs all'!$A$2:$A$108, 0), MATCH('השוואת פקטורים'!L$6, טבלה1[[#Headers],[SPPR_1986]:[SPPR_symbolic_full_import_as_DC]], 0)), INDEX(טבלה2[[SPPR_1986]:[SPPR_symbolic_full_import_as_DC]], MATCH('השוואת פקטורים'!$B9, 'PPRs inner'!$A$2:$A$108, 0), MATCH('השוואת פקטורים'!M$6, טבלה2[[#Headers],[SPPR_1986]:[SPPR_symbolic_full_import_as_DC]], 0)) / INDEX(טבלה2[[SPPR_1986]:[SPPR_symbolic_full_import_as_DC]], MATCH('השוואת פקטורים'!$B9, 'PPRs inner'!$A$2:$A$108, 0), MATCH('השוואת פקטורים'!L$6, טבלה2[[#Headers],[SPPR_1986]:[SPPR_symbolic_full_import_as_DC]], 0)) ) -> 348.92326 | N9: =IF($B$4="סהכ", INDEX(טבלה1[[SPPR_1986]:[SPPR_symbolic_full_import_as_DC]], MATCH('השוואת פקטורים'!$B9, 'PPRs all'!$A$2:$A$108, 0), MATCH('השוואת פקטורים'!N$6, טבלה1[[#Headers],[SPPR_1986]:[SPPR_symbolic_full_import_as_DC]], 0)) / INDEX(טבלה1[[SPPR_1986]:[SPPR_symbolic_full_import_as_DC]], MATCH('השוואת פקטורים'!$B9, 'PPRs all'!$A$2:$A$108, 0), MATCH('השוואת פקטורים'!M$6, טבלה1[[#Headers],[SPPR_1986]:[SPPR_symbolic_full_import_as_DC]], 0)), INDEX(טבלה2[[SPPR_1986]:[SPPR_symbolic_full_import_as_DC]], MATCH('השוואת פקטורים'!$B9, 'PPRs inner'!$A$2:$A$108, 0), MATCH('השוואת פקטורים'!N$6, טבלה2[[#Headers],[SPPR_1986]:[SPPR_symbolic_full_import_as_DC]], 0)) / INDEX(טבלה2[[SPPR_1986]:[SPPR_symbolic_full_import_as_DC]], MATCH('השוואת פקטורים'!$B9, 'PPRs inner'!$A$2:$A$108, 0), MATCH('השוואת פקטורים'!M$6, טבלה2[[#Headers],[SPPR_1986]:[SPPR_symbolic_full_import_as_DC]], 0)) ) -> 32.143334 | O9: =IF($B$4="סהכ", INDEX(טבלה1[[SPPR_1986]:[SPPR_symbolic_full_import_as_DC]], MATCH('השוואת פקטורים'!$B9, 'PPRs all'!$A$2:$A$108, 0), MATCH('השוואת פקטורים'!O$6, טבלה1[[#Headers],[SPPR_1986]:[SPPR_symbolic_full_import_as_DC]], 0)) / INDEX(טבלה1[[SPPR_1986]:[SPPR_symbolic_full_import_as_DC]], MATCH('השוואת פקטורים'!$B9, 'PPRs all'!$A$2:$A$108, 0), MATCH('השוואת פקטורים'!N$6, טבלה1[[#Headers],[SPPR_1986]:[SPPR_symbolic_full_import_as_DC]], 0)), INDEX(טבלה2[[SPPR_1986]:[SPPR_symbolic_full_import_as_DC]], MATCH('השוואת פקטורים'!$B9, 'PPRs inner'!$A$2:$A$108, 0), MATCH('השוואת פקטורים'!O$6, טבלה2[[#Headers],[SPPR_1986]:[SPPR_symbolic_full_import_as_DC]], 0)) / INDEX(טבלה2[[SPPR_1986]:[SPPR_symbolic_full_import_as_DC]], MATCH('השוואת פקטורים'!$B9, 'PPRs inner'!$A$2:$A$108, 0), MATCH('השוואת פקטורים'!N$6, טבלה2[[#Headers],[SPPR_1986]:[SPPR_symbolic_full_import_as_DC]], 0)) ) -> 1 | P9: =IF($B$4="סהכ", INDEX(טבלה1[[SPPR_1986]:[SPPR_symbolic_full_import_as_DC]], MATCH('השוואת פקטורים'!$B9, 'PPRs all'!$A$2:$A$108, 0), MATCH('השוואת פקטורים'!P$6, טבלה1[[#Headers],[SPPR_1986]:[SPPR_symbolic_full_import_as_DC]], 0)) / INDEX(טבלה1[[SPPR_1986]:[SPPR_symbolic_full_import_as_DC]], MATCH('השוואת פקטורים'!$B9, 'PPRs all'!$A$2:$A$108, 0), MATCH('השוואת פקטורים'!O$6, טבלה1[[#Headers],[SPPR_1986]:[SPPR_symbolic_full_import_as_DC]], 0)), INDEX(טבלה2[[SPPR_1986]:[SPPR_symbolic_full_import_as_DC]], MATCH('השוואת פקטורים'!$B9, 'PPRs inner'!$A$2:$A$108, 0), MATCH('השוואת פקטורים'!P$6, טבלה2[[#Headers],[SPPR_1986]:[SPPR_symbolic_full_import_as_DC]], 0)) / INDEX(טבלה2[[SPPR_1986]:[SPPR_symbolic_full_import_as_DC]], MATCH('השוואת פקטורים'!$B9, 'PPRs inner'!$A$2:$A$108, 0), MATCH('השוואת פקטורים'!O$6, טבלה2[[#Headers],[SPPR_1986]:[SPPR_symbolic_full_import_as_DC]], 0)) ) -> 0.014538195 | Q9: =IF($B$4="סהכ", INDEX(טבלה1[[SPPR_1986]:[SPPR_symbolic_full_import_as_DC]], MATCH('השוואת פקטורים'!$B9, 'PPRs all'!$A$2:$A$108, 0), MATCH('השוואת פקטורים'!Q$6, טבלה1[[#Headers],[SPPR_1986]:[SPPR_symbolic_full_import_as_DC]], 0)) / INDEX(טבלה1[[SPPR_1986]:[SPPR_symbolic_full_import_as_DC]], MATCH('השוואת פקטורים'!$B9, 'PPRs all'!$A$2:$A$108, 0), MATCH('השוואת פקטורים'!P$6, טבלה1[[#Headers],[SPPR_1986]:[SPPR_symbolic_full_import_as_DC]], 0)), INDEX(טבלה2[[SPPR_1986]:[SPPR_symbolic_full_import_as_DC]], MATCH('השוואת פקטורים'!$B9, 'PPRs inner'!$A$2:$A$108, 0), MATCH('השוואת פקטורים'!Q$6, טבלה2[[#Headers],[SPPR_1986]:[SPPR_symbolic_full_import_as_DC]], 0)) / INDEX(טבלה2[[SPPR_1986]:[SPPR_symbolic_full_import_as_DC]], MATCH('השוואת פקטורים'!$B9, 'PPRs inner'!$A$2:$A$108, 0), MATCH('השוואת פקטורים'!P$6, טבלה2[[#Headers],[SPPR_1986]:[SPPR_symbolic_full_import_as_DC]], 0)) ) -> 1 | R9: =IF($B$4="סהכ", INDEX(טבלה1[[SPPR_1986]:[SPPR_symbolic_full_import_as_DC]], MATCH('השוואת פקטורים'!$B9, 'PPRs all'!$A$2:$A$108, 0), MATCH('השוואת פקטורים'!R$6, טבלה1[[#Headers],[SPPR_1986]:[SPPR_symbolic_full_import_as_DC]], 0)) / INDEX(טבלה1[[SPPR_1986]:[SPPR_symbolic_full_import_as_DC]], MATCH('השוואת פקטורים'!$B9, 'PPRs all'!$A$2:$A$108, 0), MATCH('השוואת פקטורים'!Q$6, טבלה1[[#Headers],[SPPR_1986]:[SPPR_symbolic_full_import_as_DC]], 0)), INDEX(טבלה2[[SPPR_1986]:[SPPR_symbolic_full_import_as_DC]], MATCH('השוואת פקטורים'!$B9, 'PPRs inner'!$A$2:$A$108, 0), MATCH('השוואת פקטורים'!R$6, טבלה2[[#Headers],[SPPR_1986]:[SPPR_symbolic_full_import_as_DC]], 0)) / INDEX(טבלה2[[SPPR_1986]:[SPPR_symbolic_full_import_as_DC]], MATCH('השוואת פקטורים'!$B9, 'PPRs inner'!$A$2:$A$108, 0), MATCH('השוואת פקטורים'!Q$6, טבלה2[[#Headers],[SPPR_1986]:[SPPR_symbolic_full_import_as_DC]], 0)) ) -> 1 | ... U9: =IF($B$4="סהכ", INDEX(טבלה1[[SPPR_1986]:[SPPR_symbolic_full_import_as_DC]], MATCH('השוואת פקטורים'!$B9, 'PPRs all'!$A$2:$A$108, 0), MATCH('השוואת פקטורים'!U$6, טבלה1[[#Headers],[SPPR_1986]:[SPPR_symbolic_full_import_as_DC]], 0)) / INDEX(טבלה1[[SPPR_1986]:[SPPR_symbolic_full_import_as_DC]], MATCH('השוואת פקטורים'!$B9, 'PPRs all'!$A$2:$A$108, 0), MATCH('השוואת פקטורים'!T$6, טבלה1[[#Headers],[SPPR_1986]:[SPPR_symbolic_full_import_as_DC]], 0)), INDEX(טבלה2[[SPPR_1986]:[SPPR_symbolic_full_import_as_DC]], MATCH('השוואת פקטורים'!$B9, 'PPRs inner'!$A$2:$A$108, 0), MATCH('השוואת פקטורים'!U$6, טבלה2[[#Headers],[SPPR_1986]:[SPPR_symbolic_full_import_as_DC]], 0)) / INDEX(טבלה2[[SPPR_1986]:[SPPR_symbolic_full_import_as_DC]], MATCH('השוואת פקטורים'!$B9, 'PPRs inner'!$A$2:$A$108, 0), MATCH('השוואת פקטורים'!T$6, טבלה2[[#Headers],[SPPR_1986]:[SPPR_symbolic_full_import_as_DC]], 0)) ) -> 1 | Z9: =PRODUCT(K9:Y9) -> 40.843276
B10: [29] Central Atlantic 1990 | C10: TRUE | D10: TRUE | E10: TRUE | F10: =AND(C10:E10) -> TRUE | G10: =ABS(INDEX(טבלה5[[SPPR_1986]:[SPPR_symbolic_full_import_as_DC]],MATCH('השוואת פקטורים'!$B10,טבלה5[עמודה1],0),MATCH($C$4,טבלה5[[#Headers],[SPPR_1986]:[SPPR_symbolic_full_import_as_DC]],0))) < 5 -> TRUE | H10: =INDEX(טבלה3[[SPPR_1986]:[SPPR_symbolic_full_import_as_DC]],MATCH('השוואת פקטורים'!$B10,טבלה3[עמודה1],0),MATCH($C$4,טבלה3[[#Headers],[SPPR_1986]:[SPPR_symbolic_full_import_as_DC]],0)) -> TRUE | I10: =AND(C10:H10) -> TRUE | K10: =IF($B$4="סהכ", INDEX(טבלה1[[SPPR_1986]:[SPPR_symbolic_full_import_as_DC]], MATCH('השוואת פקטורים'!$B10, 'PPRs all'!$A$2:$A$108, 0), MATCH('השוואת פקטורים'!K$6, טבלה1[[#Headers],[SPPR_1986]:[SPPR_symbolic_full_import_as_DC]], 0)) / INDEX(טבלה1[[SPPR_1986]:[SPPR_symbolic_full_import_as_DC]], MATCH('השוואת פקטורים'!$B10, 'PPRs all'!$A$2:$A$108, 0), MATCH('השוואת פקטורים'!J$6, טבלה1[[#Headers],[SPPR_1986]:[SPPR_symbolic_full_import_as_DC]], 0)), INDEX(טבלה2[[SPPR_1986]:[SPPR_symbolic_full_import_as_DC]], MATCH('השוואת פקטורים'!$B10, 'PPRs inner'!$A$2:$A$108, 0), MATCH('השוואת פקטורים'!K$6, טבלה2[[#Headers],[SPPR_1986]:[SPPR_symbolic_full_import_as_DC]], 0)) / INDEX(טבלה2[[SPPR_1986]:[SPPR_symbolic_full_import_as_DC]], MATCH('השוואת פקטורים'!$B10, 'PPRs inner'!$A$2:$A$108, 0), MATCH('השוואת פקטורים'!J$6, טבלה2[[#Headers],[SPPR_1986]:[SPPR_symbolic_full_import_as_DC]], 0)) ) -> 0.90552414 | L10: =IF($B$4="סהכ", INDEX(טבלה1[[SPPR_1986]:[SPPR_symbolic_full_import_as_DC]], MATCH('השוואת פקטורים'!$B10, 'PPRs all'!$A$2:$A$108, 0), MATCH('השוואת פקטורים'!L$6, טבלה1[[#Headers],[SPPR_1986]:[SPPR_symbolic_full_import_as_DC]], 0)) / INDEX(טבלה1[[SPPR_1986]:[SPPR_symbolic_full_import_as_DC]], MATCH('השוואת פקטורים'!$B10, 'PPRs all'!$A$2:$A$108, 0), MATCH('השוואת פקטורים'!K$6, טבלה1[[#Headers],[SPPR_1986]:[SPPR_symbolic_full_import_as_DC]], 0)), INDEX(טבלה2[[SPPR_1986]:[SPPR_symbolic_full_import_as_DC]], MATCH('השוואת פקטורים'!$B10, 'PPRs inner'!$A$2:$A$108, 0), MATCH('השוואת פקטורים'!L$6, טבלה2[[#Headers],[SPPR_1986]:[SPPR_symbolic_full_import_as_DC]], 0)) / INDEX(טבלה2[[SPPR_1986]:[SPPR_symbolic_full_import_as_DC]], MATCH('השוואת פקטורים'!$B10, 'PPRs inner'!$A$2:$A$108, 0), MATCH('השוואת פקטורים'!K$6, טבלה2[[#Headers],[SPPR_1986]:[SPPR_symbolic_full_import_as_DC]], 0)) ) -> 4.5675378 | M10: =IF($B$4="סהכ", INDEX(טבלה1[[SPPR_1986]:[SPPR_symbolic_full_import_as_DC]], MATCH('השוואת פקטורים'!$B10, 'PPRs all'!$A$2:$A$108, 0), MATCH('השוואת פקטורים'!M$6, טבלה1[[#Headers],[SPPR_1986]:[SPPR_symbolic_full_import_as_DC]], 0)) / INDEX(טבלה1[[SPPR_1986]:[SPPR_symbolic_full_import_as_DC]], MATCH('השוואת פקטורים'!$B10, 'PPRs all'!$A$2:$A$108, 0), MATCH('השוואת פקטורים'!L$6, טבלה1[[#Headers],[SPPR_1986]:[SPPR_symbolic_full_import_as_DC]], 0)), INDEX(טבלה2[[SPPR_1986]:[SPPR_symbolic_full_import_as_DC]], MATCH('השוואת פקטורים'!$B10, 'PPRs inner'!$A$2:$A$108, 0), MATCH('השוואת פקטורים'!M$6, טבלה2[[#Headers],[SPPR_1986]:[SPPR_symbolic_full_import_as_DC]], 0)) / INDEX(טבלה2[[SPPR_1986]:[SPPR_symbolic_full_import_as_DC]], MATCH('השוואת פקטורים'!$B10, 'PPRs inner'!$A$2:$A$108, 0), MATCH('השוואת פקטורים'!L$6, טבלה2[[#Headers],[SPPR_1986]:[SPPR_symbolic_full_import_as_DC]], 0)) ) -> 6.8435394 | N10: =IF($B$4="סהכ", INDEX(טבלה1[[SPPR_1986]:[SPPR_symbolic_full_import_as_DC]], MATCH('השוואת פקטורים'!$B10, 'PPRs all'!$A$2:$A$108, 0), MATCH('השוואת פקטורים'!N$6, טבלה1[[#Headers],[SPPR_1986]:[SPPR_symbolic_full_import_as_DC]], 0)) / INDEX(טבלה1[[SPPR_1986]:[SPPR_symbolic_full_import_as_DC]], MATCH('השוואת פקטורים'!$B10, 'PPRs all'!$A$2:$A$108, 0), MATCH('השוואת פקטורים'!M$6, טבלה1[[#Headers],[SPPR_1986]:[SPPR_symbolic_full_import_as_DC]], 0)), INDEX(טבלה2[[SPPR_1986]:[SPPR_symbolic_full_import_as_DC]], MATCH('השוואת פקטורים'!$B10, 'PPRs inner'!$A$2:$A$108, 0), MATCH('השוואת פקטורים'!N$6, טבלה2[[#Headers],[SPPR_1986]:[SPPR_symbolic_full_import_as_DC]], 0)) / INDEX(טבלה2[[SPPR_1986]:[SPPR_symbolic_full_import_as_DC]], MATCH('השוואת פקטורים'!$B10, 'PPRs inner'!$A$2:$A$108, 0), MATCH('השוואת פקטורים'!M$6, טבלה2[[#Headers],[SPPR_1986]:[SPPR_symbolic_full_import_as_DC]], 0)) ) -> 4.8025785 | O10: =IF($B$4="סהכ", INDEX(טבלה1[[SPPR_1986]:[SPPR_symbolic_full_import_as_DC]], MATCH('השוואת פקטורים'!$B10, 'PPRs all'!$A$2:$A$108, 0), MATCH('השוואת פקטורים'!O$6, טבלה1[[#Headers],[SPPR_1986]:[SPPR_symbolic_full_import_as_DC]], 0)) / INDEX(טבלה1[[SPPR_1986]:[SPPR_symbolic_full_import_as_DC]], MATCH('השוואת פקטורים'!$B10, 'PPRs all'!$A$2:$A$108, 0), MATCH('השוואת פקטורים'!N$6, טבלה1[[#Headers],[SPPR_1986]:[SPPR_symbolic_full_import_as_DC]], 0)), INDEX(טבלה2[[SPPR_1986]:[SPPR_symbolic_full_import_as_DC]], MATCH('השוואת פקטורים'!$B10, 'PPRs inner'!$A$2:$A$108, 0), MATCH('השוואת פקטורים'!O$6, טבלה2[[#Headers],[SPPR_1986]:[SPPR_symbolic_full_import_as_DC]], 0)) / INDEX(טבלה2[[SPPR_1986]:[SPPR_symbolic_full_import_as_DC]], MATCH('השוואת פקטורים'!$B10, 'PPRs inner'!$A$2:$A$108, 0), MATCH('השוואת פקטורים'!N$6, טבלה2[[#Headers],[SPPR_1986]:[SPPR_symbolic_full_import_as_DC]], 0)) ) -> 1 | P10: =IF($B$4="סהכ", INDEX(טבלה1[[SPPR_1986]:[SPPR_symbolic_full_import_as_DC]], MATCH('השוואת פקטורים'!$B10, 'PPRs all'!$A$2:$A$108, 0), MATCH('השוואת פקטורים'!P$6, טבלה1[[#Headers],[SPPR_1986]:[SPPR_symbolic_full_import_as_DC]], 0)) / INDEX(טבלה1[[SPPR_1986]:[SPPR_symbolic_full_import_as_DC]], MATCH('השוואת פקטורים'!$B10, 'PPRs all'!$A$2:$A$108, 0), MATCH('השוואת פקטורים'!O$6, טבלה1[[#Headers],[SPPR_1986]:[SPPR_symbolic_full_import_as_DC]], 0)), INDEX(טבלה2[[SPPR_1986]:[SPPR_symbolic_full_import_as_DC]], MATCH('השוואת פקטורים'!$B10, 'PPRs inner'!$A$2:$A$108, 0), MATCH('השוואת פקטורים'!P$6, טבלה2[[#Headers],[SPPR_1986]:[SPPR_symbolic_full_import_as_DC]], 0)) / INDEX(טבלה2[[SPPR_1986]:[SPPR_symbolic_full_import_as_DC]], MATCH('השוואת פקטורים'!$B10, 'PPRs inner'!$A$2:$A$108, 0), MATCH('השוואת פקטורים'!O$6, טבלה2[[#Headers],[SPPR_1986]:[SPPR_symbolic_full_import_as_DC]], 0)) ) -> 0.12521116 | Q10: =IF($B$4="סהכ", INDEX(טבלה1[[SPPR_1986]:[SPPR_symbolic_full_import_as_DC]], MATCH('השוואת פקטורים'!$B10, 'PPRs all'!$A$2:$A$108, 0), MATCH('השוואת פקטורים'!Q$6, טבלה1[[#Headers],[SPPR_1986]:[SPPR_symbolic_full_import_as_DC]], 0)) / INDEX(טבלה1[[SPPR_1986]:[SPPR_symbolic_full_import_as_DC]], MATCH('השוואת פקטורים'!$B10, 'PPRs all'!$A$2:$A$108, 0), MATCH('השוואת פקטורים'!P$6, טבלה1[[#Headers],[SPPR_1986]:[SPPR_symbolic_full_import_as_DC]], 0)), INDEX(טבלה2[[SPPR_1986]:[SPPR_symbolic_full_import_as_DC]], MATCH('השוואת פקטורים'!$B10, 'PPRs inner'!$A$2:$A$108, 0), MATCH('השוואת פקטורים'!Q$6, טבלה2[[#Headers],[SPPR_1986]:[SPPR_symbolic_full_import_as_DC]], 0)) / INDEX(טבלה2[[SPPR_1986]:[SPPR_symbolic_full_import_as_DC]], MATCH('השוואת פקטורים'!$B10, 'PPRs inner'!$A$2:$A$108, 0), MATCH('השוואת פקטורים'!P$6, טבלה2[[#Headers],[SPPR_1986]:[SPPR_symbolic_full_import_as_DC]], 0)) ) -> 1 | R10: =IF($B$4="סהכ", INDEX(טבלה1[[SPPR_1986]:[SPPR_symbolic_full_import_as_DC]], MATCH('השוואת פקטורים'!$B10, 'PPRs all'!$A$2:$A$108, 0), MATCH('השוואת פקטורים'!R$6, טבלה1[[#Headers],[SPPR_1986]:[SPPR_symbolic_full_import_as_DC]], 0)) / INDEX(טבלה1[[SPPR_1986]:[SPPR_symbolic_full_import_as_DC]], MATCH('השוואת פקטורים'!$B10, 'PPRs all'!$A$2:$A$108, 0), MATCH('השוואת פקטורים'!Q$6, טבלה1[[#Headers],[SPPR_1986]:[SPPR_symbolic_full_import_as_DC]], 0)), INDEX(טבלה2[[SPPR_1986]:[SPPR_symbolic_full_import_as_DC]], MATCH('השוואת פקטורים'!$B10, 'PPRs inner'!$A$2:$A$108, 0), MATCH('השוואת פקטורים'!R$6, טבלה2[[#Headers],[SPPR_1986]:[SPPR_symbolic_full_import_as_DC]], 0)) / INDEX(טבלה2[[SPPR_1986]:[SPPR_symbolic_full_import_as_DC]], MATCH('השוואת פקטורים'!$B10, 'PPRs inner'!$A$2:$A$108, 0), MATCH('השוואת פקטורים'!Q$6, טבלה2[[#Headers],[SPPR_1986]:[SPPR_symbolic_full_import_as_DC]], 0)) ) -> 1 | ... U10: =IF($B$4="סהכ", INDEX(טבלה1[[SPPR_1986]:[SPPR_symbolic_full_import_as_DC]], MATCH('השוואת פקטורים'!$B10, 'PPRs all'!$A$2:$A$108, 0), MATCH('השוואת פקטורים'!U$6, טבלה1[[#Headers],[SPPR_1986]:[SPPR_symbolic_full_import_as_DC]], 0)) / INDEX(טבלה1[[SPPR_1986]:[SPPR_symbolic_full_import_as_DC]], MATCH('השוואת פקטורים'!$B10, 'PPRs all'!$A$2:$A$108, 0), MATCH('השוואת פקטורים'!T$6, טבלה1[[#Headers],[SPPR_1986]:[SPPR_symbolic_full_import_as_DC]], 0)), INDEX(טבלה2[[SPPR_1986]:[SPPR_symbolic_full_import_as_DC]], MATCH('השוואת פקטורים'!$B10, 'PPRs inner'!$A$2:$A$108, 0), MATCH('השוואת פקטורים'!U$6, טבלה2[[#Headers],[SPPR_1986]:[SPPR_symbolic_full_import_as_DC]], 0)) / INDEX(טבלה2[[SPPR_1986]:[SPPR_symbolic_full_import_as_DC]], MATCH('השוואת פקטורים'!$B10, 'PPRs inner'!$A$2:$A$108, 0), MATCH('השוואת פקטורים'!T$6, טבלה2[[#Headers],[SPPR_1986]:[SPPR_symbolic_full_import_as_DC]], 0)) ) -> 1 | Z10: =PRODUCT(K10:Y10) -> 17.020819
B11: [40] Eastern Scotian Shelf 1980 | C11: TRUE | D11: TRUE | E11: TRUE | F11: =AND(C11:E11) -> TRUE | G11: =ABS(INDEX(טבלה5[[SPPR_1986]:[SPPR_symbolic_full_import_as_DC]],MATCH('השוואת פקטורים'!$B11,טבלה5[עמודה1],0),MATCH($C$4,טבלה5[[#Headers],[SPPR_1986]:[SPPR_symbolic_full_import_as_DC]],0))) < 5 -> TRUE | H11: =INDEX(טבלה3[[SPPR_1986]:[SPPR_symbolic_full_import_as_DC]],MATCH('השוואת פקטורים'!$B11,טבלה3[עמודה1],0),MATCH($C$4,טבלה3[[#Headers],[SPPR_1986]:[SPPR_symbolic_full_import_as_DC]],0)) -> TRUE | I11: =AND(C11:H11) -> TRUE | K11: =IF($B$4="סהכ", INDEX(טבלה1[[SPPR_1986]:[SPPR_symbolic_full_import_as_DC]], MATCH('השוואת פקטורים'!$B11, 'PPRs all'!$A$2:$A$108, 0), MATCH('השוואת פקטורים'!K$6, טבלה1[[#Headers],[SPPR_1986]:[SPPR_symbolic_full_import_as_DC]], 0)) / INDEX(טבלה1[[SPPR_1986]:[SPPR_symbolic_full_import_as_DC]], MATCH('השוואת פקטורים'!$B11, 'PPRs all'!$A$2:$A$108, 0), MATCH('השוואת פקטורים'!J$6, טבלה1[[#Headers],[SPPR_1986]:[SPPR_symbolic_full_import_as_DC]], 0)), INDEX(טבלה2[[SPPR_1986]:[SPPR_symbolic_full_import_as_DC]], MATCH('השוואת פקטורים'!$B11, 'PPRs inner'!$A$2:$A$108, 0), MATCH('השוואת פקטורים'!K$6, טבלה2[[#Headers],[SPPR_1986]:[SPPR_symbolic_full_import_as_DC]], 0)) / INDEX(טבלה2[[SPPR_1986]:[SPPR_symbolic_full_import_as_DC]], MATCH('השוואת פקטורים'!$B11, 'PPRs inner'!$A$2:$A$108, 0), MATCH('השוואת פקטורים'!J$6, טבלה2[[#Headers],[SPPR_1986]:[SPPR_symbolic_full_import_as_DC]], 0)) ) -> 0.4877326 | L11: =IF($B$4="סהכ", INDEX(טבלה1[[SPPR_1986]:[SPPR_symbolic_full_import_as_DC]], MATCH('השוואת פקטורים'!$B11, 'PPRs all'!$A$2:$A$108, 0), MATCH('השוואת פקטורים'!L$6, טבלה1[[#Headers],[SPPR_1986]:[SPPR_symbolic_full_import_as_DC]], 0)) / INDEX(טבלה1[[SPPR_1986]:[SPPR_symbolic_full_import_as_DC]], MATCH('השוואת פקטורים'!$B11, 'PPRs all'!$A$2:$A$108, 0), MATCH('השוואת פקטורים'!K$6, טבלה1[[#Headers],[SPPR_1986]:[SPPR_symbolic_full_import_as_DC]], 0)), INDEX(טבלה2[[SPPR_1986]:[SPPR_symbolic_full_import_as_DC]], MATCH('השוואת פקטורים'!$B11, 'PPRs inner'!$A$2:$A$108, 0), MATCH('השוואת פקטורים'!L$6, טבלה2[[#Headers],[SPPR_1986]:[SPPR_symbolic_full_import_as_DC]], 0)) / INDEX(טבלה2[[SPPR_1986]:[SPPR_symbolic_full_import_as_DC]], MATCH('השוואת פקטורים'!$B11, 'PPRs inner'!$A$2:$A$108, 0), MATCH('השוואת פקטורים'!K$6, טבלה2[[#Headers],[SPPR_1986]:[SPPR_symbolic_full_import_as_DC]], 0)) ) -> 3.0612065 | M11: =IF($B$4="סהכ", INDEX(טבלה1[[SPPR_1986]:[SPPR_symbolic_full_import_as_DC]], MATCH('השוואת פקטורים'!$B11, 'PPRs all'!$A$2:$A$108, 0), MATCH('השוואת פקטורים'!M$6, טבלה1[[#Headers],[SPPR_1986]:[SPPR_symbolic_full_import_as_DC]], 0)) / INDEX(טבלה1[[SPPR_1986]:[SPPR_symbolic_full_import_as_DC]], MATCH('השוואת פקטורים'!$B11, 'PPRs all'!$A$2:$A$108, 0), MATCH('השוואת פקטורים'!L$6, טבלה1[[#Headers],[SPPR_1986]:[SPPR_symbolic_full_import_as_DC]], 0)), INDEX(טבלה2[[SPPR_1986]:[SPPR_symbolic_full_import_as_DC]], MATCH('השוואת פקטורים'!$B11, 'PPRs inner'!$A$2:$A$108, 0), MATCH('השוואת פקטורים'!M$6, טבלה2[[#Headers],[SPPR_1986]:[SPPR_symbolic_full_import_as_DC]], 0)) / INDEX(טבלה2[[SPPR_1986]:[SPPR_symbolic_full_import_as_DC]], MATCH('השוואת פקטורים'!$B11, 'PPRs inner'!$A$2:$A$108, 0), MATCH('השוואת פקטורים'!L$6, טבלה2[[#Headers],[SPPR_1986]:[SPPR_symbolic_full_import_as_DC]], 0)) ) -> 2.1857864 | N11: =IF($B$4="סהכ", INDEX(טבלה1[[SPPR_1986]:[SPPR_symbolic_full_import_as_DC]], MATCH('השוואת פקטורים'!$B11, 'PPRs all'!$A$2:$A$108, 0), MATCH('השוואת פקטורים'!N$6, טבלה1[[#Headers],[SPPR_1986]:[SPPR_symbolic_full_import_as_DC]], 0)) / INDEX(טבלה1[[SPPR_1986]:[SPPR_symbolic_full_import_as_DC]], MATCH('השוואת פקטורים'!$B11, 'PPRs all'!$A$2:$A$108, 0), MATCH('השוואת פקטורים'!M$6, טבלה1[[#Headers],[SPPR_1986]:[SPPR_symbolic_full_import_as_DC]], 0)), INDEX(טבלה2[[SPPR_1986]:[SPPR_symbolic_full_import_as_DC]], MATCH('השוואת פקטורים'!$B11, 'PPRs inner'!$A$2:$A$108, 0), MATCH('השוואת פקטורים'!N$6, טבלה2[[#Headers],[SPPR_1986]:[SPPR_symbolic_full_import_as_DC]], 0)) / INDEX(טבלה2[[SPPR_1986]:[SPPR_symbolic_full_import_as_DC]], MATCH('השוואת פקטורים'!$B11, 'PPRs inner'!$A$2:$A$108, 0), MATCH('השוואת פקטורים'!M$6, טבלה2[[#Headers],[SPPR_1986]:[SPPR_symbolic_full_import_as_DC]], 0)) ) -> 1.1220209 | O11: =IF($B$4="סהכ", INDEX(טבלה1[[SPPR_1986]:[SPPR_symbolic_full_import_as_DC]], MATCH('השוואת פקטורים'!$B11, 'PPRs all'!$A$2:$A$108, 0), MATCH('השוואת פקטורים'!O$6, טבלה1[[#Headers],[SPPR_1986]:[SPPR_symbolic_full_import_as_DC]], 0)) / INDEX(טבלה1[[SPPR_1986]:[SPPR_symbolic_full_import_as_DC]], MATCH('השוואת פקטורים'!$B11, 'PPRs all'!$A$2:$A$108, 0), MATCH('השוואת פקטורים'!N$6, טבלה1[[#Headers],[SPPR_1986]:[SPPR_symbolic_full_import_as_DC]], 0)), INDEX(טבלה2[[SPPR_1986]:[SPPR_symbolic_full_import_as_DC]], MATCH('השוואת פקטורים'!$B11, 'PPRs inner'!$A$2:$A$108, 0), MATCH('השוואת פקטורים'!O$6, טבלה2[[#Headers],[SPPR_1986]:[SPPR_symbolic_full_import_as_DC]], 0)) / INDEX(טבלה2[[SPPR_1986]:[SPPR_symbolic_full_import_as_DC]], MATCH('השוואת פקטורים'!$B11, 'PPRs inner'!$A$2:$A$108, 0), MATCH('השוואת פקטורים'!N$6, טבלה2[[#Headers],[SPPR_1986]:[SPPR_symbolic_full_import_as_DC]], 0)) ) -> 1 | P11: =IF($B$4="סהכ", INDEX(טבלה1[[SPPR_1986]:[SPPR_symbolic_full_import_as_DC]], MATCH('השוואת פקטורים'!$B11, 'PPRs all'!$A$2:$A$108, 0), MATCH('השוואת פקטורים'!P$6, טבלה1[[#Headers],[SPPR_1986]:[SPPR_symbolic_full_import_as_DC]], 0)) / INDEX(טבלה1[[SPPR_1986]:[SPPR_symbolic_full_import_as_DC]], MATCH('השוואת פקטורים'!$B11, 'PPRs all'!$A$2:$A$108, 0), MATCH('השוואת פקטורים'!O$6, טבלה1[[#Headers],[SPPR_1986]:[SPPR_symbolic_full_import_as_DC]], 0)), INDEX(טבלה2[[SPPR_1986]:[SPPR_symbolic_full_import_as_DC]], MATCH('השוואת פקטורים'!$B11, 'PPRs inner'!$A$2:$A$108, 0), MATCH('השוואת פקטורים'!P$6, טבלה2[[#Headers],[SPPR_1986]:[SPPR_symbolic_full_import_as_DC]], 0)) / INDEX(טבלה2[[SPPR_1986]:[SPPR_symbolic_full_import_as_DC]], MATCH('השוואת פקטורים'!$B11, 'PPRs inner'!$A$2:$A$108, 0), MATCH('השוואת פקטורים'!O$6, טבלה2[[#Headers],[SPPR_1986]:[SPPR_symbolic_full_import_as_DC]], 0)) ) -> 0.23914922 | Q11: =IF($B$4="סהכ", INDEX(טבלה1[[SPPR_1986]:[SPPR_symbolic_full_import_as_DC]], MATCH('השוואת פקטורים'!$B11, 'PPRs all'!$A$2:$A$108, 0), MATCH('השוואת פקטורים'!Q$6, טבלה1[[#Headers],[SPPR_1986]:[SPPR_symbolic_full_import_as_DC]], 0)) / INDEX(טבלה1[[SPPR_1986]:[SPPR_symbolic_full_import_as_DC]], MATCH('השוואת פקטורים'!$B11, 'PPRs all'!$A$2:$A$108, 0), MATCH('השוואת פקטורים'!P$6, טבלה1[[#Headers],[SPPR_1986]:[SPPR_symbolic_full_import_as_DC]], 0)), INDEX(טבלה2[[SPPR_1986]:[SPPR_symbolic_full_import_as_DC]], MATCH('השוואת פקטורים'!$B11, 'PPRs inner'!$A$2:$A$108, 0), MATCH('השוואת פקטורים'!Q$6, טבלה2[[#Headers],[SPPR_1986]:[SPPR_symbolic_full_import_as_DC]], 0)) / INDEX(טבלה2[[SPPR_1986]:[SPPR_symbolic_full_import_as_DC]], MATCH('השוואת פקטורים'!$B11, 'PPRs inner'!$A$2:$A$108, 0), MATCH('השוואת פקטורים'!P$6, טבלה2[[#Headers],[SPPR_1986]:[SPPR_symbolic_full_import_as_DC]], 0)) ) -> 1 | R11: =IF($B$4="סהכ", INDEX(טבלה1[[SPPR_1986]:[SPPR_symbolic_full_import_as_DC]], MATCH('השוואת פקטורים'!$B11, 'PPRs all'!$A$2:$A$108, 0), MATCH('השוואת פקטורים'!R$6, טבלה1[[#Headers],[SPPR_1986]:[SPPR_symbolic_full_import_as_DC]], 0)) / INDEX(טבלה1[[SPPR_1986]:[SPPR_symbolic_full_import_as_DC]], MATCH('השוואת פקטורים'!$B11, 'PPRs all'!$A$2:$A$108, 0), MATCH('השוואת פקטורים'!Q$6, טבלה1[[#Headers],[SPPR_1986]:[SPPR_symbolic_full_import_as_DC]], 0)), INDEX(טבלה2[[SPPR_1986]:[SPPR_symbolic_full_import_as_DC]], MATCH('השוואת פקטורים'!$B11, 'PPRs inner'!$A$2:$A$108, 0), MATCH('השוואת פקטורים'!R$6, טבלה2[[#Headers],[SPPR_1986]:[SPPR_symbolic_full_import_as_DC]], 0)) / INDEX(טבלה2[[SPPR_1986]:[SPPR_symbolic_full_import_as_DC]], MATCH('השוואת פקטורים'!$B11, 'PPRs inner'!$A$2:$A$108, 0), MATCH('השוואת פקטורים'!Q$6, טבלה2[[#Headers],[SPPR_1986]:[SPPR_symbolic_full_import_as_DC]], 0)) ) -> 1.017914 | ... U11: =IF($B$4="סהכ", INDEX(טבלה1[[SPPR_1986]:[SPPR_symbolic_full_import_as_DC]], MATCH('השוואת פקטורים'!$B11, 'PPRs all'!$A$2:$A$108, 0), MATCH('השוואת פקטורים'!U$6, טבלה1[[#Headers],[SPPR_1986]:[SPPR_symbolic_full_import_as_DC]], 0)) / INDEX(טבלה1[[SPPR_1986]:[SPPR_symbolic_full_import_as_DC]], MATCH('השוואת פקטורים'!$B11, 'PPRs all'!$A$2:$A$108, 0), MATCH('השוואת פקטורים'!T$6, טבלה1[[#Headers],[SPPR_1986]:[SPPR_symbolic_full_import_as_DC]], 0)), INDEX(טבלה2[[SPPR_1986]:[SPPR_symbolic_full_import_as_DC]], MATCH('השוואת פקטורים'!$B11, 'PPRs inner'!$A$2:$A$108, 0), MATCH('השוואת פקטורים'!U$6, טבלה2[[#Headers],[SPPR_1986]:[SPPR_symbolic_full_import_as_DC]], 0)) / INDEX(טבלה2[[SPPR_1986]:[SPPR_symbolic_full_import_as_DC]], MATCH('השוואת פקטורים'!$B11, 'PPRs inner'!$A$2:$A$108, 0), MATCH('השוואת פקטורים'!T$6, טבלה2[[#Headers],[SPPR_1986]:[SPPR_symbolic_full_import_as_DC]], 0)) ) -> 0.98240129 | Z11: =PRODUCT(K11:Y11) -> 0.87569341
B12: [41] Eastern Scotian Shelf 1995 | C12: TRUE | D12: TRUE | E12: TRUE | F12: =AND(C12:E12) -> TRUE | G12: =ABS(INDEX(טבלה5[[SPPR_1986]:[SPPR_symbolic_full_import_as_DC]],MATCH('השוואת פקטורים'!$B12,טבלה5[עמודה1],0),MATCH($C$4,טבלה5[[#Headers],[SPPR_1986]:[SPPR_symbolic_full_import_as_DC]],0))) < 5 -> TRUE | H12: =INDEX(טבלה3[[SPPR_1986]:[SPPR_symbolic_full_import_as_DC]],MATCH('השוואת פקטורים'!$B12,טבלה3[עמודה1],0),MATCH($C$4,טבלה3[[#Headers],[SPPR_1986]:[SPPR_symbolic_full_import_as_DC]],0)) -> TRUE | I12: =AND(C12:H12) -> TRUE | K12: =IF($B$4="סהכ", INDEX(טבלה1[[SPPR_1986]:[SPPR_symbolic_full_import_as_DC]], MATCH('השוואת פקטורים'!$B12, 'PPRs all'!$A$2:$A$108, 0), MATCH('השוואת פקטורים'!K$6, טבלה1[[#Headers],[SPPR_1986]:[SPPR_symbolic_full_import_as_DC]], 0)) / INDEX(טבלה1[[SPPR_1986]:[SPPR_symbolic_full_import_as_DC]], MATCH('השוואת פקטורים'!$B12, 'PPRs all'!$A$2:$A$108, 0), MATCH('השוואת פקטורים'!J$6, טבלה1[[#Headers],[SPPR_1986]:[SPPR_symbolic_full_import_as_DC]], 0)), INDEX(טבלה2[[SPPR_1986]:[SPPR_symbolic_full_import_as_DC]], MATCH('השוואת פקטורים'!$B12, 'PPRs inner'!$A$2:$A$108, 0), MATCH('השוואת פקטורים'!K$6, טבלה2[[#Headers],[SPPR_1986]:[SPPR_symbolic_full_import_as_DC]], 0)) / INDEX(טבלה2[[SPPR_1986]:[SPPR_symbolic_full_import_as_DC]], MATCH('השוואת פקטורים'!$B12, 'PPRs inner'!$A$2:$A$108, 0), MATCH('השוואת פקטורים'!J$6, טבלה2[[#Headers],[SPPR_1986]:[SPPR_symbolic_full_import_as_DC]], 0)) ) -> 2.8779297 | L12: =IF($B$4="סהכ", INDEX(טבלה1[[SPPR_1986]:[SPPR_symbolic_full_import_as_DC]], MATCH('השוואת פקטורים'!$B12, 'PPRs all'!$A$2:$A$108, 0), MATCH('השוואת פקטורים'!L$6, טבלה1[[#Headers],[SPPR_1986]:[SPPR_symbolic_full_import_as_DC]], 0)) / INDEX(טבלה1[[SPPR_1986]:[SPPR_symbolic_full_import_as_DC]], MATCH('השוואת פקטורים'!$B12, 'PPRs all'!$A$2:$A$108, 0), MATCH('השוואת פקטורים'!K$6, טבלה1[[#Headers],[SPPR_1986]:[SPPR_symbolic_full_import_as_DC]], 0)), INDEX(טבלה2[[SPPR_1986]:[SPPR_symbolic_full_import_as_DC]], MATCH('השוואת פקטורים'!$B12, 'PPRs inner'!$A$2:$A$108, 0), MATCH('השוואת פקטורים'!L$6, טבלה2[[#Headers],[SPPR_1986]:[SPPR_symbolic_full_import_as_DC]], 0)) / INDEX(טבלה2[[SPPR_1986]:[SPPR_symbolic_full_import_as_DC]], MATCH('השוואת פקטורים'!$B12, 'PPRs inner'!$A$2:$A$108, 0), MATCH('השוואת פקטורים'!K$6, טבלה2[[#Headers],[SPPR_1986]:[SPPR_symbolic_full_import_as_DC]], 0)) ) -> 7.2128471 | M12: =IF($B$4="סהכ", INDEX(טבלה1[[SPPR_1986]:[SPPR_symbolic_full_import_as_DC]], MATCH('השוואת פקטורים'!$B12, 'PPRs all'!$A$2:$A$108, 0), MATCH('השוואת פקטורים'!M$6, טבלה1[[#Headers],[SPPR_1986]:[SPPR_symbolic_full_import_as_DC]], 0)) / INDEX(טבלה1[[SPPR_1986]:[SPPR_symbolic_full_import_as_DC]], MATCH('השוואת פקטורים'!$B12, 'PPRs all'!$A$2:$A$108, 0), MATCH('השוואת פקטורים'!L$6, טבלה1[[#Headers],[SPPR_1986]:[SPPR_symbolic_full_import_as_DC]], 0)), INDEX(טבלה2[[SPPR_1986]:[SPPR_symbolic_full_import_as_DC]], MATCH('השוואת פקטורים'!$B12, 'PPRs inner'!$A$2:$A$108, 0), MATCH('השוואת פקטורים'!M$6, טבלה2[[#Headers],[SPPR_1986]:[SPPR_symbolic_full_import_as_DC]], 0)) / INDEX(טבלה2[[SPPR_1986]:[SPPR_symbolic_full_import_as_DC]], MATCH('השוואת פקטורים'!$B12, 'PPRs inner'!$A$2:$A$108, 0), MATCH('השוואת פקטורים'!L$6, טבלה2[[#Headers],[SPPR_1986]:[SPPR_symbolic_full_import_as_DC]], 0)) ) -> 0.23031709 | N12: =IF($B$4="סהכ", INDEX(טבלה1[[SPPR_1986]:[SPPR_symbolic_full_import_as_DC]], MATCH('השוואת פקטורים'!$B12, 'PPRs all'!$A$2:$A$108, 0), MATCH('השוואת פקטורים'!N$6, טבלה1[[#Headers],[SPPR_1986]:[SPPR_symbolic_full_import_as_DC]], 0)) / INDEX(טבלה1[[SPPR_1986]:[SPPR_symbolic_full_import_as_DC]], MATCH('השוואת פקטורים'!$B12, 'PPRs all'!$A$2:$A$108, 0), MATCH('השוואת פקטורים'!M$6, טבלה1[[#Headers],[SPPR_1986]:[SPPR_symbolic_full_import_as_DC]], 0)), INDEX(טבלה2[[SPPR_1986]:[SPPR_symbolic_full_import_as_DC]], MATCH('השוואת פקטורים'!$B12, 'PPRs inner'!$A$2:$A$108, 0), MATCH('השוואת פקטורים'!N$6, טבלה2[[#Headers],[SPPR_1986]:[SPPR_symbolic_full_import_as_DC]], 0)) / INDEX(טבלה2[[SPPR_1986]:[SPPR_symbolic_full_import_as_DC]], MATCH('השוואת פקטורים'!$B12, 'PPRs inner'!$A$2:$A$108, 0), MATCH('השוואת פקטורים'!M$6, טבלה2[[#Headers],[SPPR_1986]:[SPPR_symbolic_full_import_as_DC]], 0)) ) -> 1.3749173 | O12: =IF($B$4="סהכ", INDEX(טבלה1[[SPPR_1986]:[SPPR_symbolic_full_import_as_DC]], MATCH('השוואת פקטורים'!$B12, 'PPRs all'!$A$2:$A$108, 0), MATCH('השוואת פקטורים'!O$6, טבלה1[[#Headers],[SPPR_1986]:[SPPR_symbolic_full_import_as_DC]], 0)) / INDEX(טבלה1[[SPPR_1986]:[SPPR_symbolic_full_import_as_DC]], MATCH('השוואת פקטורים'!$B12, 'PPRs all'!$A$2:$A$108, 0), MATCH('השוואת פקטורים'!N$6, טבלה1[[#Headers],[SPPR_1986]:[SPPR_symbolic_full_import_as_DC]], 0)), INDEX(טבלה2[[SPPR_1986]:[SPPR_symbolic_full_import_as_DC]], MATCH('השוואת פקטורים'!$B12, 'PPRs inner'!$A$2:$A$108, 0), MATCH('השוואת פקטורים'!O$6, טבלה2[[#Headers],[SPPR_1986]:[SPPR_symbolic_full_import_as_DC]], 0)) / INDEX(טבלה2[[SPPR_1986]:[SPPR_symbolic_full_import_as_DC]], MATCH('השוואת פקטורים'!$B12, 'PPRs inner'!$A$2:$A$108, 0), MATCH('השוואת פקטורים'!N$6, טבלה2[[#Headers],[SPPR_1986]:[SPPR_symbolic_full_import_as_DC]], 0)) ) -> 1 | P12: =IF($B$4="סהכ", INDEX(טבלה1[[SPPR_1986]:[SPPR_symbolic_full_import_as_DC]], MATCH('השוואת פקטורים'!$B12, 'PPRs all'!$A$2:$A$108, 0), MATCH('השוואת פקטורים'!P$6, טבלה1[[#Headers],[SPPR_1986]:[SPPR_symbolic_full_import_as_DC]], 0)) / INDEX(טבלה1[[SPPR_1986]:[SPPR_symbolic_full_import_as_DC]], MATCH('השוואת פקטורים'!$B12, 'PPRs all'!$A$2:$A$108, 0), MATCH('השוואת פקטורים'!O$6, טבלה1[[#Headers],[SPPR_1986]:[SPPR_symbolic_full_import_as_DC]], 0)), INDEX(טבלה2[[SPPR_1986]:[SPPR_symbolic_full_import_as_DC]], MATCH('השוואת פקטורים'!$B12, 'PPRs inner'!$A$2:$A$108, 0), MATCH('השוואת פקטורים'!P$6, טבלה2[[#Headers],[SPPR_1986]:[SPPR_symbolic_full_import_as_DC]], 0)) / INDEX(טבלה2[[SPPR_1986]:[SPPR_symbolic_full_import_as_DC]], MATCH('השוואת פקטורים'!$B12, 'PPRs inner'!$A$2:$A$108, 0), MATCH('השוואת פקטורים'!O$6, טבלה2[[#Headers],[SPPR_1986]:[SPPR_symbolic_full_import_as_DC]], 0)) ) -> 0.36195577 | Q12: =IF($B$4="סהכ", INDEX(טבלה1[[SPPR_1986]:[SPPR_symbolic_full_import_as_DC]], MATCH('השוואת פקטורים'!$B12, 'PPRs all'!$A$2:$A$108, 0), MATCH('השוואת פקטורים'!Q$6, טבלה1[[#Headers],[SPPR_1986]:[SPPR_symbolic_full_import_as_DC]], 0)) / INDEX(טבלה1[[SPPR_1986]:[SPPR_symbolic_full_import_as_DC]], MATCH('השוואת פקטורים'!$B12, 'PPRs all'!$A$2:$A$108, 0), MATCH('השוואת פקטורים'!P$6, טבלה1[[#Headers],[SPPR_1986]:[SPPR_symbolic_full_import_as_DC]], 0)), INDEX(טבלה2[[SPPR_1986]:[SPPR_symbolic_full_import_as_DC]], MATCH('השוואת פקטורים'!$B12, 'PPRs inner'!$A$2:$A$108, 0), MATCH('השוואת פקטורים'!Q$6, טבלה2[[#Headers],[SPPR_1986]:[SPPR_symbolic_full_import_as_DC]], 0)) / INDEX(טבלה2[[SPPR_1986]:[SPPR_symbolic_full_import_as_DC]], MATCH('השוואת פקטורים'!$B12, 'PPRs inner'!$A$2:$A$108, 0), MATCH('השוואת פקטורים'!P$6, טבלה2[[#Headers],[SPPR_1986]:[SPPR_symbolic_full_import_as_DC]], 0)) ) -> 1 | R12: =IF($B$4="סהכ", INDEX(טבלה1[[SPPR_1986]:[SPPR_symbolic_full_import_as_DC]], MATCH('השוואת פקטורים'!$B12, 'PPRs all'!$A$2:$A$108, 0), MATCH('השוואת פקטורים'!R$6, טבלה1[[#Headers],[SPPR_1986]:[SPPR_symbolic_full_import_as_DC]], 0)) / INDEX(טבלה1[[SPPR_1986]:[SPPR_symbolic_full_import_as_DC]], MATCH('השוואת פקטורים'!$B12, 'PPRs all'!$A$2:$A$108, 0), MATCH('השוואת פקטורים'!Q$6, טבלה1[[#Headers],[SPPR_1986]:[SPPR_symbolic_full_import_as_DC]], 0)), INDEX(טבלה2[[SPPR_1986]:[SPPR_symbolic_full_import_as_DC]], MATCH('השוואת פקטורים'!$B12, 'PPRs inner'!$A$2:$A$108, 0), MATCH('השוואת פקטורים'!R$6, טבלה2[[#Headers],[SPPR_1986]:[SPPR_symbolic_full_import_as_DC]], 0)) / INDEX(טבלה2[[SPPR_1986]:[SPPR_symbolic_full_import_as_DC]], MATCH('השוואת פקטורים'!$B12, 'PPRs inner'!$A$2:$A$108, 0), MATCH('השוואת פקטורים'!Q$6, טבלה2[[#Headers],[SPPR_1986]:[SPPR_symbolic_full_import_as_DC]], 0)) ) -> 1.0467444 | ... U12: =IF($B$4="סהכ", INDEX(טבלה1[[SPPR_1986]:[SPPR_symbolic_full_import_as_DC]], MATCH('השוואת פקטורים'!$B12, 'PPRs all'!$A$2:$A$108, 0), MATCH('השוואת פקטורים'!U$6, טבלה1[[#Headers],[SPPR_1986]:[SPPR_symbolic_full_import_as_DC]], 0)) / INDEX(טבלה1[[SPPR_1986]:[SPPR_symbolic_full_import_as_DC]], MATCH('השוואת פקטורים'!$B12, 'PPRs all'!$A$2:$A$108, 0), MATCH('השוואת פקטורים'!T$6, טבלה1[[#Headers],[SPPR_1986]:[SPPR_symbolic_full_import_as_DC]], 0)), INDEX(טבלה2[[SPPR_1986]:[SPPR_symbolic_full_import_as_DC]], MATCH('השוואת פקטורים'!$B12, 'PPRs inner'!$A$2:$A$108, 0), MATCH('השוואת פקטורים'!U$6, טבלה2[[#Headers],[SPPR_1986]:[SPPR_symbolic_full_import_as_DC]], 0)) / INDEX(טבלה2[[SPPR_1986]:[SPPR_symbolic_full_import_as_DC]], MATCH('השוואת פקטורים'!$B12, 'PPRs inner'!$A$2:$A$108, 0), MATCH('השוואת פקטורים'!T$6, טבלה2[[#Headers],[SPPR_1986]:[SPPR_symbolic_full_import_as_DC]], 0)) ) -> 0.9553431 | Z12: =PRODUCT(K12:Y12) -> 2.3792779
